Workbook

Sheet Information
A1: Event | B1: Spring Classic
A2: Year | B2: 2023
A3: Location | B3: Gull Lake
A4: Participants | B4: Spartan Dawgs | C4: Invited Guests
B5: James | C5: Dillon
B6: Dan | C6: Corey
B7: Kyle | C7: Andy
B8: Brett | C8: Joe Pa
B9: Jon | C9: Juan
B10: Tovey | C10: Connor
B11: Cole | C11: Bud
B12: Matt | C12: Vince
A14: Lodging Information | B14: Villa 1 | C14: Villa 2 | D14: Villa 3 | E14: Villa 4
B15: Dan | C15: Jon | D15: Connor | E15: Kyle
B16: Cole | C16: Juan | D16: Vince | E16: Tovey
B17: JoePa | C17: Matt | D17: James | E17: Brett
B18: Corey | C18: Bud | D18: Dillon | E18: Andy
C20: Multiplier | D20: 1 | E20: 0.4 | F20: 0.7 | G20: 0.6
A21: Index | C21: Index | D21: Standard | E21: Scramble | F21: Alt | G21: Chapman
B22: James | C22: 16 | D22: =$C22*D$20 -> 16 | E22: =$C22*E$20 -> 6.4 | F22: =$C22*F$20 -> 11.2 | G22: =$C22*G$20 -> 9.6
B23: Dan | C23: 7.8 | D23: =$C23*D$20 -> 7.8 | E23: =$C23*E$20 -> 3.12 | F23: =$C23*F$20 -> 5.46 | G23: =$C23*G$20 -> 4.68
B24: Kyle | C24: 10.4 | D24: =$C24*D$20 -> 10.4 | E24: =$C24*E$20 -> 4.16 | F24: =$C24*F$20 -> 7.28 | G24: =$C24*G$20 -> 6.24
B25: Brett | C25: 12.9 | D25: =$C25*D$20 -> 12.9 | E25: =$C25*E$20 -> 5.16 | F25: =$C25*F$20 -> 9.03 | G25: =$C25*G$20 -> 7.74
B26: Jon | C26: 21.9 | D26: =$C26*D$20 -> 21.9 | E26: =$C26*E$20 -> 8.76 | F26: =$C26*F$20 -> 15.33 | G26: =$C26*G$20 -> 13.14
B27: Tovey | C27: 14.5 | D27: =$C27*D$20 -> 14.5 | E27: =$C27*E$20 -> 5.8 | F27: =$C27*F$20 -> 10.15 | G27: =$C27*G$20 -> 8.7
B28: Cole | C28: 12 | D28: =$C28*D$20 -> 12 | E28: =$C28*E$20 -> 4.8 | F28: =$C28*F$20 -> 8.4 | G28: =$C28*G$20 -> 7.2
B29: Matt | C29: 30 | D29: =$C29*D$20 -> 30 | E29: =$C29*E$20 -> 12 | F29: =$C29*F$20 -> 21 | G29: =$C29*G$20 -> 18
B30: Dillon | C30: 16.6 | D30: =$C30*D$20 -> 16.6 | E30: =$C30*E$20 -> 6.64 | F30: =$C30*F$20 -> 11.62 | G30: =$C30*G$20 -> 9.96
B31: Corey | C31: 12 | D31: =$C31*D$20 -> 12 | E31: =$C31*E$20 -> 4.8 | F31: =$C31*F$20 -> 8.4 | G31: =$C31*G$20 -> 7.2
B32: Andy | C32: 9.8 | D32: =$C32*D$20 -> 9.8 | E32: =$C32*E$20 -> 3.92 | F32: =$C32*F$20 -> 6.86 | G32: =$C32*G$20 -> 5.88
B33: JoePa | C33: 10.3 | D33: =$C33*D$20 -> 10.3 | E33: =$C33*E$20 -> 4.12 | F33: =$C33*F$20 -> 7.21 | G33: =$C33*G$20 -> 6.18
... B37: Vince | C37: 17.7 | D37: =$C37*D$20 -> 17.7 | E37: =$C37*E$20 -> 7.08 | F37: =$C37*F$20 -> 12.39 | G37: =$C37*G$20 -> 10.62

Sheet Friday
C1: Friday, Stoatin Brae, 18, BB, BB
D2: Stoatin Brae | E2: 1st Tee | I2: 2nd Tee | M2: 3rd Tee | Q2: 4th Tee | Y2: SD | Z2: IG
A3: Golfer | B3: Course Handicap | E3: Cole | G3: Connor | I3: Brett | K3: Bud | M3: Kyle | O3: Dillon | Q3: Dan | S3: JoePa | Y3: =SUM(Y78,Y83,Y88,Y93) -> 1.5 | Z3: =SUM(Z78,Z83,Z88,Z93) -> 2.5
A4: =Information!B22 -> James | B4: =VLOOKUP(A4,$A$21:$B$39,2,false) -> 16 | F4: VS | J4: VS | N4: VS | R4: VS
A5: =Information!B23 -> Dan | B5: =VLOOKUP(A5,$A$21:$B$39,2,false) -> 7.8 | E5: Tovey | G5: Andy | I5: Matt | K5: Vince | M5: James | O5: Juan | Q5: Jon | S5: Corey
A6: =Information!B24 -> Kyle | B6: =VLOOKUP(A6,$A$21:$B$39,2,false) -> 10.4
A7: =Information!B25 -> Brett | B7: =VLOOKUP(A7,$A$21:$B$39,2,false) -> 12.9 | D7: Team Stroke Total | E7: =(VLOOKUP(E3,Information!$B$22:$C$37,2,false))+(VLOOKUP(E5,Information!$B$22:$C$37,2,false)) -> 26.5 | G7: =(VLOOKUP(G3,Information!$B$22:$C$37,2,false))+(VLOOKUP(G5,Information!$B$22:$C$37,2,false)) -> 25.8 | I7: =(VLOOKUP(I3,Information!$B$22:$C$37,2,false))+(VLOOKUP(I5,Information!$B$22:$C$37,2,false)) -> 42.9 | K7: =(VLOOKUP(K3,Information!$B$22:$C$37,2,false))+(VLOOKUP(K5,Information!$B$22:$C$37,2,false)) -> 35.7 | M7: =(VLOOKUP(M3,Information!$B$22:$C$37,2,false))+(VLOOKUP(M5,Information!$B$22:$C$37,2,false)) -> 26.4 | O7: =(VLOOKUP(O3,Information!$B$22:$C$37,2,false))+(VLOOKUP(O5,Information!$B$22:$C$37,2,false)) -> 31.8 | Q7: =(VLOOKUP(Q3,Information!$B$22:$C$37,2,false))+(VLOOKUP(Q5,Information!$B$22:$C$37,2,false)) -> 29.7 | S7: =(VLOOKUP(S3,Information!$B$22:$C$37,2,false))+(VLOOKUP(S5,Information!$B$22:$C$37,2,false)) -> 22.3
A8: =Information!B26 -> Jon | B8: =VLOOKUP(A8,$A$21:$B$39,2,false) -> 21.9
A9: =Information!B27 -> Tovey | B9: =VLOOKUP(A9,$A$21:$B$39,2,false) -> 14.5
A10: =Information!B28 -> Cole | B10: =VLOOKUP(A10,$A$21:$B$39,2,false) -> 12 | D10: Format | E10: Best Ball | N10: Best Ball
A11: =Information!B29 -> Matt | B11: =VLOOKUP(A11,$A$21:$B$39,2,false) -> 30 | D11: Hole | E11: 1 | F11: 2 | G11: 3 | H11: 4 | I11: 5 | J11: 6 | K11: 7 | L11: 8 | M11: 9 | N11: 10 | O11: 11 | P11: 12 | Q11: 13 | R11: 14 | S11: 15 | T11: 16 | U11: 17 | V11: 18
A12: =Information!B30 -> Dillon | B12: =VLOOKUP(A12,$A$21:$B$39,2,false) -> 16.6 | D12: Par | E12: 4 | F12: 3 | G12: 4 | H12: 4 | I12: 4 | J12: 5 | K12: 3 | L12: 4 | M12: 5 | N12: 4 | O12: 3 | P12: 4 | Q12: 4 | R12: 3 | S12: 4 | T12: 5 | U12: 3 | V12: 5
A13: =Information!B31 -> Corey | B13: =VLOOKUP(A13,$A$21:$B$39,2,false) -> 12 | D13: Handicap | E13: 13 | F13: 15 | G13: 5 | H13: 1 | I13: 3 | J13: 9 | K13: 17 | L13: 11 | M13: 7 | N13: 6 | O13: 16 | P13: 8 | Q13: 2 | R13: 18 | S13: 12 | T13: 10 | U13: 14 | V13: 4
A14: =Information!B32 -> Andy | B14: =VLOOKUP(A14,$A$21:$B$39,2,false) -> 9.8
A15: =Information!B33 -> JoePa | B15: =VLOOKUP(A15,$A$21:$B$39,2,false) -> 10.3 | D15: Hole | E15: 1 | F15: 2 | G15: 3 | H15: 4 | I15: 5 | J15: 6 | K15: 7 | L15: 8 | M15: 9 | N15: 10 | O15: 11 | P15: 12 | Q15: 13 | R15: 14 | S15: 15 | T15: 16 | U15: 17 | V15: 18 | X15: Front Total | Y15: Back Total | Z15: Grand Total
A16: =Information!B34 -> Juan | B16: =VLOOKUP(A16,$A$21:$B$39,2,false) -> 15.2 | C16: Score | D16: =A21 -> Cole | E16: 5 | F16: 4 | G16: 5 | H16: 7 | I16: 5 | J16: 7 | K16: 3 | L16: 5 | M16: 7 | N16: 6 | O16: 5 | P16: 5 | Q16: 6 | R16: 4 | S16: 4 | T16: 6 | U16: 4 | V16: 6 | X16: =SUM(E16:M16) -> 48 | Y16: =SUM(N16:V16) -> 46 | Z16: =sum(X16,Y16) -> 94
A17: =Information!B35 -> Connor | B17: =VLOOKUP(A17,$A$21:$B$39,2,false) -> 16 | D17: =A22 -> Tovey | E17: 5 | F17: 6 | G17: 4 | H17: 4 | I17: 5 | J17: 5 | K17: 4 | L17: 5 | M17: 8 | N17: 5 | O17: 3 | P17: 4 | Q17: 7 | R17: 4 | S17: 5 | T17: 4 | U17: 3 | V17: 7 | X17: =SUM(E17:M17) -> 46 | Y17: =SUM(N17:V17) -> 42 | Z17: =sum(X17,Y17) -> 88
A18: =Information!B36 -> Bud | B18: =VLOOKUP(A18,$A$21:$B$39,2,false) -> 18 | D18: =A23 -> Connor | E18: 8 | F18: 6 | G18: 8 | H18: 8 | I18: 8 | J18: 10 | K18: 6 | L18: 7 | M18: 8 | N18: 5 | O18: 4 | P18: 5 | Q18: 7 | R18: 4 | S18: 4 | T18: 5 | U18: 4 | V18: 6 | X18: =SUM(E18:M18) -> 69 | Y18: =SUM(N18:V18) -> 44 | Z18: =sum(X18,Y18) -> 113
A19: =Information!B37 -> Vince | B19: =VLOOKUP(A19,$A$21:$B$39,2,false) -> 17.7 | D19: =A24 -> Andy | E19: 3 | F19: 4 | G19: 5 | H19: 7 | I19: 5 | J19: 5 | K19: 3 | L19: 4 | M19: 5 | N19: 5 | O19: 3 | P19: 5 | Q19: 7 | R19: 3 | S19: 5 | T19: 6 | U19: 3 | V19: 5 | X19: =SUM(E19:M19) -> 41 | Y19: =SUM(N19:V19) -> 42 | Z19: =sum(X19,Y19) -> 83
D20: =A25
A21: =E3 -> Cole | B21: =VLOOKUP(A21, Information!$B$22:$G$37, 3, FALSE) -> 12 | C21: Score | D21: =A26 -> Brett | E21: 4 | F21: 4 | G21: 5 | H21: 6 | I21: 6 | J21: 8 | K21: 3 | L21: 7 | M21: 6 | N21: 5 | O21: 6 | P21: 6 | Q21: 6 | R21: 5 | S21: 4 | T21: 6 | U21: 3 | V21: 6 | X21: =SUM(E21:M21) -> 49 | Y21: =SUM(N21:V21) -> 47 | Z21: =sum(X21,Y21) -> 96
A22: =E5 -> Tovey | B22: =VLOOKUP(A22, Information!$B$22:$G$37, 3, FALSE) -> 14.5 | D22: =A27 -> Matt | E22: 6 | F22: 5 | G22: 5 | H22: 6 | I22: 8 | J22: 9 | K22: 5 | L22: 7 | M22: 7 | N22: 6 | O22: 7 | P22: 6 | Q22: 6 | R22: 5 | S22: 5 | T22: 7 | U22: 5 | V22: 7 | X22: =SUM(E22:M22) -> 58 | Y22: =SUM(N22:V22) -> 54 | Z22: =sum(X22,Y22) -> 112
A23: =G3 -> Connor | B23: =VLOOKUP(A23, Information!$B$22:$G$37, 3, FALSE) -> 16 | D23: =A28 -> Bud | E23: 6 | F23: 3 | G23: 7 | H23: 7 | I23: 6 | J23: 7 | K23: 4 | L23: 5 | M23: 7 | N23: 5 | O23: 4 | P23: 5 | Q23: 7 | R23: 6 | S23: 6 | T23: 6 | U23: 5 | V23: 7 | X23: =SUM(E23:M23) -> 52 | Y23: =SUM(N23:V23) -> 51 | Z23: =sum(X23,Y23) -> 103
A24: =G5 -> Andy | B24: =VLOOKUP(A24, Information!$B$22:$G$37, 3, FALSE) -> 9.8 | D24: =A29 -> Vince | E24: 5 | F24: 4 | G24: 6 | H24: 6 | I24: 5 | J24: 8 | K24: 4 | L24: 6 | M24: 6 | N24: 5 | O24: 3 | P24: 4 | Q24: 7 | R24: 5 | S24: 6 | T24: 6 | U24: 5 | V24: 6 | X24: =SUM(E24:M24) -> 50 | Y24: =SUM(N24:V24) -> 47 | Z24: =sum(X24,Y24) -> 97
D25: =A30
A26: =I3 -> Brett | B26: =VLOOKUP(A26, Information!$B$22:$G$37, 3, FALSE) -> 12.9 | C26: Score | D26: =A31 -> Kyle | E26: =ROUNDUP(RANDBETWEEN(2,9)) -> 7 | F26: =ROUNDUP(RANDBETWEEN(2,9)) -> 7 | G26: =ROUNDUP(RANDBETWEEN(2,9)) -> 2 | H26: =ROUNDUP(RANDBETWEEN(2,9)) -> 4 | I26: =ROUNDUP(RANDBETWEEN(2,9)) -> 6 | J26: =ROUNDUP(RANDBETWEEN(2,9)) -> 4 | K26: =ROUNDUP(RANDBETWEEN(2,9)) -> 8 | L26: =ROUNDUP(RANDBETWEEN(2,9)) -> 9 | ... V26: =ROUNDUP(RANDBETWEEN(2,9)) -> 9 | X26: =SUM(E26:M26) -> 53 | Y26: =SUM(N26:V26) -> 50 | Z26: =sum(X26,Y26) -> 103
A27: =I5 -> Matt | B27: =VLOOKUP(A27, Information!$B$22:$G$37, 3, FALSE) -> 30 | D27: =A32 -> James | E27: =ROUNDUP(RANDBETWEEN(2,9)) -> 8 | F27: =ROUNDUP(RANDBETWEEN(2,9)) -> 8 | G27: =ROUNDUP(RANDBETWEEN(2,9)) -> 9 | H27: =ROUNDUP(RANDBETWEEN(2,9)) -> 3 | I27: =ROUNDUP(RANDBETWEEN(2,9)) -> 5 | J27: =ROUNDUP(RANDBETWEEN(2,9)) -> 4 | K27: =ROUNDUP(RANDBETWEEN(2,9)) -> 3 | L27: =ROUNDUP(RANDBETWEEN(2,9)) -> 8 | ... V27: =ROUNDUP(RANDBETWEEN(2,9)) -> 6 | X27: =SUM(E27:M27) -> 56 | Y27: =SUM(N27:V27) -> 52 | Z27: =sum(X27,Y27) -> 108
A28: =K3 -> Bud | B28: =VLOOKUP(A28, Information!$B$22:$G$37, 3, FALSE) -> 18 | D28: =A33 -> Dillon | E28: =ROUNDUP(RANDBETWEEN(2,9)) -> 3 | F28: =ROUNDUP(RANDBETWEEN(2,9)) -> 7 | G28: =ROUNDUP(RANDBETWEEN(2,9)) -> 2 | H28: =ROUNDUP(RANDBETWEEN(2,9)) -> 2 | I28: =ROUNDUP(RANDBETWEEN(2,9)) -> 7 | J28: =ROUNDUP(RANDBETWEEN(2,9)) -> 3 | K28: =ROUNDUP(RANDBETWEEN(2,9)) -> 9 | L28: =ROUNDUP(RANDBETWEEN(2,9)) -> 3 | ... V28: =ROUNDUP(RANDBETWEEN(2,9)) -> 7 | X28: =SUM(E28:M28) -> 44 | Y28: =SUM(N28:V28) -> 39 | Z28: =sum(X28,Y28) -> 83
A29: =K5 -> Vince | B29: =VLOOKUP(A29, Information!$B$22:$G$37, 3, FALSE) -> 17.7 | D29: =A34 -> Juan | E29: =ROUNDUP(RANDBETWEEN(2,9)) -> 8 | F29: =ROUNDUP(RANDBETWEEN(2,9)) -> 4 | G29: =ROUNDUP(RANDBETWEEN(2,9)) -> 4 | H29: =ROUNDUP(RANDBETWEEN(2,9)) -> 6 | I29: =ROUNDUP(RANDBETWEEN(2,9)) -> 8 | J29: =ROUNDUP(RANDBETWEEN(2,9)) -> 9 | K29: =ROUNDUP(RANDBETWEEN(2,9)) -> 8 | L29: =ROUNDUP(RANDBETWEEN(2,9)) -> 8 | ... V29: =ROUNDUP(RANDBETWEEN(2,9)) -> 5 | X29: =SUM(E29:M29) -> 60 | Y29: =SUM(N29:V29) -> 57 | Z29: =sum(X29,Y29) -> 117
D30: =A35
A31: =M3 -> Kyle | B31: =VLOOKUP(A31, Information!$B$22:$G$37, 3, FALSE) -> 10.4 | C31: Score | D31: =A36 -> Dan | E31: 4 | F31: 3 | G31: 3 | H31: 5 | I31: 4 | J31: 5 | K31: 3 | L31: 4 | M31: 5 | N31: 4 | O31: 3 | P31: 4 | Q31: 5 | R31: 3 | S31: 5 | T31: 6 | U31: 3 | V31: 5 | X31: =SUM(E31:M31) -> 36 | Y31: =SUM(N31:V31) -> 38 | Z31: =sum(X31,Y31) -> 74
A32: =M5 -> James | B32: =VLOOKUP(A32, Information!$B$22:$G$37, 3, FALSE) -> 16 | D32: =A37 -> Jon | E32: 4 | F32: 6 | G32: 5 | H32: 7 | I32: 6 | J32: 6 | K32: 4 | L32: 4 | M32: 5 | N32: 5 | O32: 4 | P32: 5 | Q32: 8 | R32: 4 | S32: 6 | T32: 6 | U32: 3 | V32: 6 | X32: =SUM(E32:M32) -> 47 | Y32: =SUM(N32:V32) -> 47 | Z32: =sum(X32,Y32) -> 94
A33: =O3 -> Dillon | B33: =VLOOKUP(A33, Information!$B$22:$G$37, 3, FALSE) -> 16.6 | D33: =A38 -> JoePa | E33: 4 | F33: 4 | G33: 4 | H33: 5 | I33: 5 | J33: 6 | K33: 4 | L33: 4 | M33: 7 | N33: 5 | O33: 5 | P33: 4 | Q33: 6 | R33: 4 | S33: 5 | T33: 6 | U33: 4 | V33: 5 | X33: =SUM(E33:M33) -> 43 | Y33: =SUM(N33:V33) -> 44 | Z33: =sum(X33,Y33) -> 87
A34: =O5 -> Juan | B34: =VLOOKUP(A34, Information!$B$22:$G$37, 3, FALSE) -> 15.2 | D34: =A39 -> Corey | E34: 4 | F34: 4 | G34: 7 | H34: 6 | I34: 5 | J34: 6 | K34: 3 | L34: 6 | M34: 5 | N34: 5 | O34: 4 | P34: 5 | Q34: 5 | R34: 3 | S34: 4 | T34: 6 | U34: 3 | V34: 5 | X34: =SUM(E34:M34) -> 46 | Y34: =SUM(N34:V34) -> 40 | Z34: =sum(X34,Y34) -> 86
A36: =Q3 -> Dan | B36: =VLOOKUP(A36, Information!$B$22:$G$37, 3, FALSE) -> 7.8 | C36: Strokes | D36: =D16 -> Cole | E36: =IF(VLOOKUP($D36,$A$4:$B$19,2,FALSE)>=E$13,1,0) -> 0 | F36: =IF(VLOOKUP($D36,$A$4:$B$19,2,FALSE)>=F$13,1,0) -> 0 | G36: =IF(VLOOKUP($D36,$A$4:$B$19,2,FALSE)>=G$13,1,0) -> 1 | H36: =IF(VLOOKUP($D36,$A$4:$B$19,2,FALSE)>=H$13,1,0) -> 1 | I36: =IF(VLOOKUP($D36,$A$4:$B$19,2,FALSE)>=I$13,1,0) -> 1 | J36: =IF(VLOOKUP($D36,$A$4:$B$19,2,FALSE)>=J$13,1,0) -> 1 | K36: =IF(VLOOKUP($D36,$A$4:$B$19,2,FALSE)>=K$13,1,0) -> 0 | L36: =IF(VLOOKUP($D36,$A$4:$B$19,2,FALSE)>=L$13,1,0) -> 1 | ... V36: =IF(VLOOKUP($D36,$A$4:$B$19,2,FALSE)>=V$13,1,0) -> 1 | X36: =SUM(E36:M36) -> 6 | Y36: =SUM(N36:V36) -> 6 | Z36: =sum(X36,Y36) -> 12
A37: =Q5 -> Jon | B37: =VLOOKUP(A37, Information!$B$22:$G$37, 3, FALSE) -> 21.9 | D37: =D17 -> Tovey | E37: =IF(VLOOKUP($D37,$A$4:$B$19,2,FALSE)>=E$13,1,0) -> 1 | F37: =IF(VLOOKUP($D37,$A$4:$B$19,2,FALSE)>=F$13,1,0) -> 0 | G37: =IF(VLOOKUP($D37,$A$4:$B$19,2,FALSE)>=G$13,1,0) -> 1 | H37: =IF(VLOOKUP($D37,$A$4:$B$19,2,FALSE)>=H$13,1,0) -> 1 | I37: =IF(VLOOKUP($D37,$A$4:$B$19,2,FALSE)>=I$13,1,0) -> 1 | J37: =IF(VLOOKUP($D37,$A$4:$B$19,2,FALSE)>=J$13,1,0) -> 1 | K37: =IF(VLOOKUP($D37,$A$4:$B$19,2,FALSE)>=K$13,1,0) -> 0 | L37: =IF(VLOOKUP($D37,$A$4:$B$19,2,FALSE)>=L$13,1,0) -> 1 | ... V37: =IF(VLOOKUP($D37,$A$4:$B$19,2,FALSE)>=V$13,1,0) -> 1 | X37: =SUM(E37:M37) -> 7 | Y37: =SUM(N37:V37) -> 7 | Z37: =sum(X37,Y37) -> 14
A38: =S3 -> JoePa | B38: =VLOOKUP(A38, Information!$B$22:$G$37, 3, FALSE) -> 10.3 | D38: =D18 -> Connor | E38: =IF(VLOOKUP($D38,$A$4:$B$19,2,FALSE)>=E$13,1,0) -> 1 | F38: =IF(VLOOKUP($D38,$A$4:$B$19,2,FALSE)>=F$13,1,0) -> 1 | G38: =IF(VLOOKUP($D38,$A$4:$B$19,2,FALSE)>=G$13,1,0) -> 1 | H38: =IF(VLOOKUP($D38,$A$4:$B$19,2,FALSE)>=H$13,1,0) -> 1 | I38: =IF(VLOOKUP($D38,$A$4:$B$19,2,FALSE)>=I$13,1,0) -> 1 | J38: =IF(VLOOKUP($D38,$A$4:$B$19,2,FALSE)>=J$13,1,0) -> 1 | K38: =IF(VLOOKUP($D38,$A$4:$B$19,2,FALSE)>=K$13,1,0) -> 0 | L38: =IF(VLOOKUP($D38,$A$4:$B$19,2,FALSE)>=L$13,1,0) -> 1 | ... V38: =IF(VLOOKUP($D38,$A$4:$B$19,2,FALSE)>=V$13,1,0) -> 1 | X38: =SUM(E38:M38) -> 8 | Y38: =SUM(N38:V38) -> 8 | Z38: =sum(X38,Y38) -> 16
A39: =S5 -> Corey | B39: =VLOOKUP(A39, Information!$B$22:$G$37, 3, FALSE) -> 12 | D39: =D19 -> Andy | E39: =IF(VLOOKUP($D39,$A$4:$B$19,2,FALSE)>=E$13,1,0) -> 0 | F39: =IF(VLOOKUP($D39,$A$4:$B$19,2,FALSE)>=F$13,1,0) -> 0 | G39: =IF(VLOOKUP($D39,$A$4:$B$19,2,FALSE)>=G$13,1,0) -> 1 | H39: =IF(VLOOKUP($D39,$A$4:$B$19,2,FALSE)>=H$13,1,0) -> 1 | I39: =IF(VLOOKUP($D39,$A$4:$B$19,2,FALSE)>=I$13,1,0) -> 1 | J39: =IF(VLOOKUP($D39,$A$4:$B$19,2,FALSE)>=J$13,1,0) -> 1 | K39: =IF(VLOOKUP($D39,$A$4:$B$19,2,FALSE)>=K$13,1,0) -> 0 | L39: =IF(VLOOKUP($D39,$A$4:$B$19,2,FALSE)>=L$13,1,0) -> 0 | ... V39: =IF(VLOOKUP($D39,$A$4:$B$19,2,FALSE)>=V$13,1,0) -> 1 | X39: =SUM(E39:M39) -> 5 | Y39: =SUM(N39:V39) -> 4 | Z39: =sum(X39,Y39) -> 9
D40: =D20
C41: Strokes | D41: =D21 -> Brett | E41: =IF(VLOOKUP($D41,$A$4:$B$19,2,FALSE)>=E$13,1,0) -> 0 | F41: =IF(VLOOKUP($D41,$A$4:$B$19,2,FALSE)>=F$13,1,0) -> 0 | G41: =IF(VLOOKUP($D41,$A$4:$B$19,2,FALSE)>=G$13,1,0) -> 1 | H41: =IF(VLOOKUP($D41,$A$4:$B$19,2,FALSE)>=H$13,1,0) -> 1 | I41: =IF(VLOOKUP($D41,$A$4:$B$19,2,FALSE)>=I$13,1,0) -> 1 | J41: =IF(VLOOKUP($D41,$A$4:$B$19,2,FALSE)>=J$13,1,0) -> 1 | K41: =IF(VLOOKUP($D41,$A$4:$B$19,2,FALSE)>=K$13,1,0) -> 0 | L41: =IF(VLOOKUP($D41,$A$4:$B$19,2,FALSE)>=L$13,1,0) -> 1 | ... V41: =IF(VLOOKUP($D41,$A$4:$B$19,2,FALSE)>=V$13,1,0) -> 1 | X41: =SUM(E41:M41) -> 6 | Y41: =SUM(N41:V41) -> 6 | Z41: =sum(X41,Y41) -> 12
...

Sheet Saturday (AM)
C1: Saturday (AM), Course, Scramble, AltShot
D2: Stoatin Brae | E2: 1st Tee | I2: 2nd Tee | M2: 3rd Tee | Q2: 4th Tee | Y2: SD | Z2: IG
A3: Golfer | B3: Course Handicap | E3: Cole | G3: Connor | I3: Brett | K3: Bud | M3: Kyle | O3: Dillon | Q3: Dan | S3: JoePa | Y3: =SUM(Y79,Y84,Y89,Y94) -> 2 | Z3: =SUM(Z79,Z84,Z89,Z94) -> 2
A4: =Information!B22 -> James | B4: =VLOOKUP(A4,$A$21:$B$39,2,false) -> #N/A | F4: VS | J4: VS | N4: VS | R4: VS
A5: =Information!B23 -> Dan | B5: =VLOOKUP(A5,$A$21:$B$39,2,false) -> #N/A | E5: Tovey | G5: Andy | I5: Matt | K5: Vince | M5: James | O5: Juan | Q5: Jon | S5: Corey
A6: =Information!B24 -> Kyle | B6: =VLOOKUP(A6,$A$21:$B$39,2,false) -> #N/A
A7: =Information!B25 -> Brett | B7: =VLOOKUP(A7,$A$21:$B$39,2,false) -> #N/A | D7: Team Stroke Total | E7: =(VLOOKUP(E3,Information!$B$22:$C$37,2,false))+(VLOOKUP(E5,Information!$B$22:$C$37,2,false)) -> 26.5 | G7: =(VLOOKUP(G3,Information!$B$22:$C$37,2,false))+(VLOOKUP(G5,Information!$B$22:$C$37,2,false)) -> 25.8 | I7: =(VLOOKUP(I3,Information!$B$22:$C$37,2,false))+(VLOOKUP(I5,Information!$B$22:$C$37,2,false)) -> 42.9 | K7: =(VLOOKUP(K3,Information!$B$22:$C$37,2,false))+(VLOOKUP(K5,Information!$B$22:$C$37,2,false)) -> 35.7 | M7: =(VLOOKUP(M3,Information!$B$22:$C$37,2,false))+(VLOOKUP(M5,Information!$B$22:$C$37,2,false)) -> 26.4 | O7: =(VLOOKUP(O3,Information!$B$22:$C$37,2,false))+(VLOOKUP(O5,Information!$B$22:$C$37,2,false)) -> 31.8 | Q7: =(VLOOKUP(Q3,Information!$B$22:$C$37,2,false))+(VLOOKUP(Q5,Information!$B$22:$C$37,2,false)) -> 29.7 | S7: =(VLOOKUP(S3,Information!$B$22:$C$37,2,false))+(VLOOKUP(S5,Information!$B$22:$C$37,2,false)) -> 22.3
A8: =Information!B26 -> Jon | B8: =VLOOKUP(A8,$A$21:$B$39,2,false) -> #N/A
A9: =Information!B27 -> Tovey | B9: =VLOOKUP(A9,$A$21:$B$39,2,false) -> #N/A
A10: =Information!B28 -> Cole | B10: =VLOOKUP(A10,$A$21:$B$39,2,false) -> #N/A | D10: Format | E10: Scramble | N10: AltShot
A11: =Information!B29 -> Matt | B11: =VLOOKUP(A11,$A$21:$B$39,2,false) -> #N/A | D11: Hole | E11: 1 | F11: 2 | G11: 3 | H11: 4 | I11: 5 | J11: 6 | K11: 7 | L11: 8 | M11: 9 | N11: 10 | O11: 11 | P11: 12 | Q11: 13 | R11: 14 | S11: 15 | T11: 16 | U11: 17 | V11: 18
A12: =Information!B30 -> Dillon | B12: =VLOOKUP(A12,$A$21:$B$39,2,false) -> #N/A | D12: Par | E12: 4 | F12: 3 | G12: 4 | H12: 4 | I12: 4 | J12: 5 | K12: 3 | L12: 4 | M12: 5 | N12: 4 | O12: 3 | P12: 4 | Q12: 4 | R12: 3 | S12: 4 | T12: 5 | U12: 3 | V12: 5
A13: =Information!B31 -> Corey | B13: =VLOOKUP(A13,$A$21:$B$39,2,false) -> #N/A | D13: Handicap | E13: 13 | F13: 15 | G13: 5 | H13: 1 | I13: 3 | J13: 9 | K13: 17 | L13: 11 | M13: 7 | N13: 6 | O13: 16 | P13: 8 | Q13: 2 | R13: 18 | S13: 12 | T13: 10 | U13: 14 | V13: 4
A14: =Information!B32 -> Andy | B14: =VLOOKUP(A14,$A$21:$B$39,2,false) -> #N/A
A15: =Information!B33 -> JoePa | B15: =VLOOKUP(A15,$A$21:$B$39,2,false) -> #N/A | D15: Hole | E15: 1 | F15: 2 | G15: 3 | H15: 4 | I15: 5 | J15: 6 | K15: 7 | L15: 8 | M15: 9 | N15: 10 | O15: 11 | P15: 12 | Q15: 13 | R15: 14 | S15: 15 | T15: 16 | U15: 17 | V15: 18 | X15: Front Total | Y15: Back Total | Z15: Grand Total
A16: =Information!B34 -> Juan | B16: =VLOOKUP(A16,$A$21:$B$39,2,false) -> #N/A | C16: Score | D16: =A21 -> ColeToveyScramble | E16: =ROUNDUP(RANDBETWEEN(2,9)) -> 5 | F16: =ROUNDUP(RANDBETWEEN(2,9)) -> 4 | G16: =ROUNDUP(RANDBETWEEN(2,9)) -> 7 | H16: =ROUNDUP(RANDBETWEEN(2,9)) -> 9 | I16: =ROUNDUP(RANDBETWEEN(2,9)) -> 6 | J16: =ROUNDUP(RANDBETWEEN(2,9)) -> 3 | K16: =ROUNDUP(RANDBETWEEN(2,9)) -> 6 | L16: =ROUNDUP(RANDBETWEEN(2,9)) -> 7 | M16: =ROUNDUP(RANDBETWEEN(2,9)) -> 5 | X16: =SUM(E16:M16) -> 52 | Y16: =SUM(N16:V16) -> 0 | Z16: =sum(X16,Y16) -> 52
A17: =Information!B35 -> Connor | B17: =VLOOKUP(A17,$A$21:$B$39,2,false) -> #N/A | D17: =A40 -> ColeToveyAltShot | N17: =ROUNDUP(RANDBETWEEN(2,9)) -> 7 | O17: =ROUNDUP(RANDBETWEEN(2,9)) -> 6 | P17: =ROUNDUP(RANDBETWEEN(2,9)) -> 7 | Q17: =ROUNDUP(RANDBETWEEN(2,9)) -> 5 | R17: =ROUNDUP(RANDBETWEEN(2,9)) -> 8 | S17: =ROUNDUP(RANDBETWEEN(2,9)) -> 5 | T17: =ROUNDUP(RANDBETWEEN(2,9)) -> 4 | U17: =ROUNDUP(RANDBETWEEN(2,9)) -> 8 | V17: =ROUNDUP(RANDBETWEEN(2,9)) -> 7 | X17: =SUM(E17:M17) -> 0 | Y17: =SUM(N17:V17) -> 57 | Z17: =sum(X17,Y17) -> 57
A18: =Information!B36 -> Bud | B18: =VLOOKUP(A18,$A$21:$B$39,2,false) -> #N/A | D18: =A23 -> ConnorAndyScramble | E18: =ROUNDUP(RANDBETWEEN(2,9)) -> 4 | F18: =ROUNDUP(RANDBETWEEN(2,9)) -> 6 | G18: =ROUNDUP(RANDBETWEEN(2,9)) -> 4 | H18: =ROUNDUP(RANDBETWEEN(2,9)) -> 7 | I18: =ROUNDUP(RANDBETWEEN(2,9)) -> 6 | J18: =ROUNDUP(RANDBETWEEN(2,9)) -> 5 | K18: =ROUNDUP(RANDBETWEEN(2,9)) -> 3 | L18: =ROUNDUP(RANDBETWEEN(2,9)) -> 8 | M18: =ROUNDUP(RANDBETWEEN(2,9)) -> 2 | X18: =SUM(E18:M18) -> 45 | Y18: =SUM(N18:V18) -> 0 | Z18: =sum(X18,Y18) -> 45
A19: =Information!B37 -> Vince | B19: =VLOOKUP(A19,$A$21:$B$39,2,false) -> #N/A | D19: =A42 -> ConnorAndyAltShot | N19: =ROUNDUP(RANDBETWEEN(2,9)) -> 7 | O19: =ROUNDUP(RANDBETWEEN(2,9)) -> 4 | P19: =ROUNDUP(RANDBETWEEN(2,9)) -> 9 | Q19: =ROUNDUP(RANDBETWEEN(2,9)) -> 9 | R19: =ROUNDUP(RANDBETWEEN(2,9)) -> 5 | S19: =ROUNDUP(RANDBETWEEN(2,9)) -> 9 | T19: =ROUNDUP(RANDBETWEEN(2,9)) -> 5 | U19: =ROUNDUP(RANDBETWEEN(2,9)) -> 5 | V19: =ROUNDUP(RANDBETWEEN(2,9)) -> 2 | X19: =SUM(E19:M19) -> 0 | Y19: =SUM(N19:V19) -> 55 | Z19: =sum(X19,Y19) -> 55
D20: =A25
A21: =$E$3&$E$5&$E$10 -> ColeToveyScramble | B21: =VLOOKUP($E$3, Information!$B$22:$G$37, 4, FALSE)+VLOOKUP($E$5, Information!$B$22:$G$37, 4, FALSE) -> 10.6 | C21: Score | D21: =A26 -> BrettMattScramble | E21: =ROUNDUP(RANDBETWEEN(2,9)) -> 2 | F21: =ROUNDUP(RANDBETWEEN(2,9)) -> 4 | G21: =ROUNDUP(RANDBETWEEN(2,9)) -> 4 | H21: =ROUNDUP(RANDBETWEEN(2,9)) -> 2 | I21: =ROUNDUP(RANDBETWEEN(2,9)) -> 4 | J21: =ROUNDUP(RANDBETWEEN(2,9)) -> 9 | K21: =ROUNDUP(RANDBETWEEN(2,9)) -> 5 | L21: =ROUNDUP(RANDBETWEEN(2,9)) -> 3 | M21: =ROUNDUP(RANDBETWEEN(2,9)) -> 2 | X21: =SUM(E21:M21) -> 35 | Y21: =SUM(N21:V21) -> 0 | Z21: =sum(X21,Y21) -> 35
D22: =A45 -> BrettMattAltShot | N22: =ROUNDUP(RANDBETWEEN(2,9)) -> 2 | O22: =ROUNDUP(RANDBETWEEN(2,9)) -> 9 | P22: =ROUNDUP(RANDBETWEEN(2,9)) -> 2 | Q22: =ROUNDUP(RANDBETWEEN(2,9)) -> 3 | R22: =ROUNDUP(RANDBETWEEN(2,9)) -> 9 | S22: =ROUNDUP(RANDBETWEEN(2,9)) -> 6 | T22: =ROUNDUP(RANDBETWEEN(2,9)) -> 3 | U22: =ROUNDUP(RANDBETWEEN(2,9)) -> 7 | V22: =ROUNDUP(RANDBETWEEN(2,9)) -> 8 | X22: =SUM(E22:M22) -> 0 | Y22: =SUM(N22:V22) -> 49 | Z22: =sum(X22,Y22) -> 49
A23: =$G$3&$G$5&$E$10 -> ConnorAndyScramble | B23: =VLOOKUP($G$3, Information!$B$22:$G$37, 4, FALSE)+VLOOKUP($G$5, Information!$B$22:$G$37, 4, FALSE) -> 10.32 | D23: =A28 -> BudVinceScramble | E23: =ROUNDUP(RANDBETWEEN(2,9)) -> 6 | F23: =ROUNDUP(RANDBETWEEN(2,9)) -> 5 | G23: =ROUNDUP(RANDBETWEEN(2,9)) -> 9 | H23: =ROUNDUP(RANDBETWEEN(2,9)) -> 5 | I23: =ROUNDUP(RANDBETWEEN(2,9)) -> 4 | J23: =ROUNDUP(RANDBETWEEN(2,9)) -> 3 | K23: =ROUNDUP(RANDBETWEEN(2,9)) -> 3 | L23: =ROUNDUP(RANDBETWEEN(2,9)) -> 8 | M23: =ROUNDUP(RANDBETWEEN(2,9)) -> 8 | X23: =SUM(E23:M23) -> 51 | Y23: =SUM(N23:V23) -> 0 | Z23: =sum(X23,Y23) -> 51
D24: =A47 -> BudVinceAltShot | N24: =ROUNDUP(RANDBETWEEN(2,9)) -> 6 | O24: =ROUNDUP(RANDBETWEEN(2,9)) -> 5 | P24: =ROUNDUP(RANDBETWEEN(2,9)) -> 6 | Q24: =ROUNDUP(RANDBETWEEN(2,9)) -> 2 | R24: =ROUNDUP(RANDBETWEEN(2,9)) -> 7 | S24: =ROUNDUP(RANDBETWEEN(2,9)) -> 7 | T24: =ROUNDUP(RANDBETWEEN(2,9)) -> 3 | U24: =ROUNDUP(RANDBETWEEN(2,9)) -> 9 | V24: =ROUNDUP(RANDBETWEEN(2,9)) -> 3 | X24: =SUM(E24:M24) -> 0 | Y24: =SUM(N24:V24) -> 48 | Z24: =sum(X24,Y24) -> 48
D25: =A30
A26: =$I$3&$I$5&$E$10 -> BrettMattScramble | B26: =VLOOKUP($I$3, Information!$B$22:$G$37, 4, FALSE)+VLOOKUP($I$5, Information!$B$22:$G$37, 4, FALSE) -> 17.16 | C26: Score | D26: =A31 -> KyleJamesScramble | E26: =ROUNDUP(RANDBETWEEN(2,9)) -> 5 | F26: =ROUNDUP(RANDBETWEEN(2,9)) -> 9 | G26: =ROUNDUP(RANDBETWEEN(2,9)) -> 7 | H26: =ROUNDUP(RANDBETWEEN(2,9)) -> 8 | I26: =ROUNDUP(RANDBETWEEN(2,9)) -> 9 | J26: =ROUNDUP(RANDBETWEEN(2,9)) -> 9 | K26: =ROUNDUP(RANDBETWEEN(2,9)) -> 2 | L26: =ROUNDUP(RANDBETWEEN(2,9)) -> 4 | M26: =ROUNDUP(RANDBETWEEN(2,9)) -> 5 | X26: =SUM(E26:M26) -> 58 | Y26: =SUM(N26:V26) -> 0 | Z26: =sum(X26,Y26) -> 58
D27: =A50 -> KyleJamesAltShot | N27: =ROUNDUP(RANDBETWEEN(2,9)) -> 9 | O27: =ROUNDUP(RANDBETWEEN(2,9)) -> 8 | P27: =ROUNDUP(RANDBETWEEN(2,9)) -> 9 | Q27: =ROUNDUP(RANDBETWEEN(2,9)) -> 3 | R27: =ROUNDUP(RANDBETWEEN(2,9)) -> 5 | S27: =ROUNDUP(RANDBETWEEN(2,9)) -> 8 | T27: =ROUNDUP(RANDBETWEEN(2,9)) -> 6 | U27: =ROUNDUP(RANDBETWEEN(2,9)) -> 7 | V27: =ROUNDUP(RANDBETWEEN(2,9)) -> 9 | X27: =SUM(E27:M27) -> 0 | Y27: =SUM(N27:V27) -> 64 | Z27: =sum(X27,Y27) -> 64
A28: =$K$3&$K$5&$E$10 -> BudVinceScramble | B28: =VLOOKUP($K$3, Information!$B$22:$G$37, 4, FALSE)+VLOOKUP($K$5, Information!$B$22:$G$37, 4, FALSE) -> 14.28 | D28: =A33 -> DillonJuanScramble | E28: =ROUNDUP(RANDBETWEEN(2,9)) -> 5 | F28: =ROUNDUP(RANDBETWEEN(2,9)) -> 2 | G28: =ROUNDUP(RANDBETWEEN(2,9)) -> 4 | H28: =ROUNDUP(RANDBETWEEN(2,9)) -> 6 | I28: =ROUNDUP(RANDBETWEEN(2,9)) -> 9 | J28: =ROUNDUP(RANDBETWEEN(2,9)) -> 7 | K28: =ROUNDUP(RANDBETWEEN(2,9)) -> 8 | L28: =ROUNDUP(RANDBETWEEN(2,9)) -> 3 | M28: =ROUNDUP(RANDBETWEEN(2,9)) -> 4 | X28: =SUM(E28:M28) -> 48 | Y28: =SUM(N28:V28) -> 0 | Z28: =sum(X28,Y28) -> 48
D29: =A52 -> DillonJuanAltShot | N29: =ROUNDUP(RANDBETWEEN(2,9)) -> 7 | O29: =ROUNDUP(RANDBETWEEN(2,9)) -> 8 | P29: =ROUNDUP(RANDBETWEEN(2,9)) -> 2 | Q29: =ROUNDUP(RANDBETWEEN(2,9)) -> 8 | R29: =ROUNDUP(RANDBETWEEN(2,9)) -> 4 | S29: =ROUNDUP(RANDBETWEEN(2,9)) -> 5 | T29: =ROUNDUP(RANDBETWEEN(2,9)) -> 9 | U29: =ROUNDUP(RANDBETWEEN(2,9)) -> 7 | V29: =ROUNDUP(RANDBETWEEN(2,9)) -> 7 | X29: =SUM(E29:M29) -> 0 | Y29: =SUM(N29:V29) -> 57 | Z29: =sum(X29,Y29) -> 57
D30: =A35
A31: =$M$3&$M$5&$E$10 -> KyleJamesScramble | B31: =VLOOKUP($M$3, Information!$B$22:$G$37, 4, FALSE)+VLOOKUP($M$5, Information!$B$22:$G$37, 4, FALSE) -> 10.56 | C31: Score | D31: =A36 -> DanJonScramble | E31: =ROUNDUP(RANDBETWEEN(2,9)) -> 8 | F31: =ROUNDUP(RANDBETWEEN(2,9)) -> 9 | G31: =ROUNDUP(RANDBETWEEN(2,9)) -> 8 | H31: =ROUNDUP(RANDBETWEEN(2,9)) -> 4 | I31: =ROUNDUP(RANDBETWEEN(2,9)) -> 6 | J31: =ROUNDUP(RANDBETWEEN(2,9)) -> 3 | K31: =ROUNDUP(RANDBETWEEN(2,9)) -> 7 | L31: =ROUNDUP(RANDBETWEEN(2,9)) -> 8 | M31: =ROUNDUP(RANDBETWEEN(2,9)) -> 4 | X31: =SUM(E31:M31) -> 57 | Y31: =SUM(N31:V31) -> 0 | Z31: =sum(X31,Y31) -> 57
D32: =A55 -> DanJonAltShot | N32: =ROUNDUP(RANDBETWEEN(2,9)) -> 6 | O32: =ROUNDUP(RANDBETWEEN(2,9)) -> 3 | P32: =ROUNDUP(RANDBETWEEN(2,9)) -> 9 | Q32: =ROUNDUP(RANDBETWEEN(2,9)) -> 6 | R32: =ROUNDUP(RANDBETWEEN(2,9)) -> 4 | S32: =ROUNDUP(RANDBETWEEN(2,9)) -> 8 | T32: =ROUNDUP(RANDBETWEEN(2,9)) -> 9 | U32: =ROUNDUP(RANDBETWEEN(2,9)) -> 4 | V32: =ROUNDUP(RANDBETWEEN(2,9)) -> 6 | X32: =SUM(E32:M32) -> 0 | Y32: =SUM(N32:V32) -> 55 | Z32: =sum(X32,Y32) -> 55
A33: =$O$3&$O$5&$E$10 -> DillonJuanScramble | B33: =VLOOKUP($O$3, Information!$B$22:$G$37, 4, FALSE)+VLOOKUP($O$5, Information!$B$22:$G$37, 4, FALSE) -> 12.72 | D33: =A38 -> JoePaCoreyScramble | E33: =ROUNDUP(RANDBETWEEN(2,9)) -> 3 | F33: =ROUNDUP(RANDBETWEEN(2,9)) -> 8 | G33: =ROUNDUP(RANDBETWEEN(2,9)) -> 3 | H33: =ROUNDUP(RANDBETWEEN(2,9)) -> 8 | I33: =ROUNDUP(RANDBETWEEN(2,9)) -> 8 | J33: =ROUNDUP(RANDBETWEEN(2,9)) -> 7 | K33: =ROUNDUP(RANDBETWEEN(2,9)) -> 4 | L33: =ROUNDUP(RANDBETWEEN(2,9)) -> 9 | M33: =ROUNDUP(RANDBETWEEN(2,9)) -> 6 | X33: =SUM(E33:M33) -> 56 | Y33: =SUM(N33:V33) -> 0 | Z33: =sum(X33,Y33) -> 56
D34: =A57 -> JoePaCoreyAltShot | N34: =ROUNDUP(RANDBETWEEN(2,9)) -> 6 | O34: =ROUNDUP(RANDBETWEEN(2,9)) -> 2 | P34: =ROUNDUP(RANDBETWEEN(2,9)) -> 8 | Q34: =ROUNDUP(RANDBETWEEN(2,9)) -> 7 | R34: =ROUNDUP(RANDBETWEEN(2,9)) -> 3 | S34: =ROUNDUP(RANDBETWEEN(2,9)) -> 3 | T34: =ROUNDUP(RANDBETWEEN(2,9)) -> 2 | U34: =ROUNDUP(RANDBETWEEN(2,9)) -> 2 | V34: =ROUNDUP(RANDBETWEEN(2,9)) -> 8 | X34: =SUM(E34:M34) -> 0 | Y34: =SUM(N34:V34) -> 41 | Z34: =sum(X34,Y34) -> 41
A36: =$Q$3&$Q$5&$E$10 -> DanJonScramble | B36: =VLOOKUP($Q$3, Information!$B$22:$G$37, 4, FALSE)+VLOOKUP($Q$5, Information!$B$22:$G$37, 4, FALSE) -> 11.88 | C36: Strokes | D36: =D16 -> ColeToveyScramble | E36: =IF(VLOOKUP($D36,$A$4:$B$57,2,FALSE)>=E$13,1,0) -> 0 | F36: =IF(VLOOKUP($D36,$A$4:$B$57,2,FALSE)>=F$13,1,0) -> 0 | G36: =IF(VLOOKUP($D36,$A$4:$B$57,2,FALSE)>=G$13,1,0) -> 1 | H36: =IF(VLOOKUP($D36,$A$4:$B$57,2,FALSE)>=H$13,1,0) -> 1 | I36: =IF(VLOOKUP($D36,$A$4:$B$57,2,FALSE)>=I$13,1,0) -> 1 | J36: =IF(VLOOKUP($D36,$A$4:$B$57,2,FALSE)>=J$13,1,0) -> 1 | K36: =IF(VLOOKUP($D36,$A$4:$B$57,2,FALSE)>=K$13,1,0) -> 0 | L36: =IF(VLOOKUP($D36,$A$4:$B$57,2,FALSE)>=L$13,1,0) -> 0 | ... V36: =IF(VLOOKUP($D36,$A$4:$B$57,2,FALSE)>=V$13,1,0) -> 1 | X36: =SUM(E36:M36) -> 5 | Y36: =SUM(N36:V36) -> 5 | Z36: =sum(X36,Y36) -> 10
D37: =D17 -> ColeToveyAltShot | E37: =IF(VLOOKUP($D37,$A$4:$B$57,2,FALSE)>=E$13,1,0) -> 1 | F37: =IF(VLOOKUP($D37,$A$4:$B$57,2,FALSE)>=F$13,1,0) -> 1 | G37: =IF(VLOOKUP($D37,$A$4:$B$57,2,FALSE)>=G$13,1,0) -> 1 | H37: =IF(VLOOKUP($D37,$A$4:$B$57,2,FALSE)>=H$13,1,0) -> 1 | I37: =IF(VLOOKUP($D37,$A$4:$B$57,2,FALSE)>=I$13,1,0) -> 1 | J37: =IF(VLOOKUP($D37,$A$4:$B$57,2,FALSE)>=J$13,1,0) -> 1 | K37: =IF(VLOOKUP($D37,$A$4:$B$57,2,FALSE)>=K$13,1,0) -> 1 | L37: =IF(VLOOKUP($D37,$A$4:$B$57,2,FALSE)>=L$13,1,0) -> 1 | ... V37: =IF(VLOOKUP($D37,$A$4:$B$57,2,FALSE)>=V$13,1,0) -> 1 | X37: =SUM(E37:M37) -> 9 | Y37: =SUM(N37:V37) -> 9 | Z37: =sum(X37,Y37) -> 18
A38: =$S$3&$S$5&$E$10 -> JoePaCoreyScramble | B38: =VLOOKUP($S$3, Information!$B$22:$G$37, 4, FALSE)+VLOOKUP($S$5, Information!$B$22:$G$37, 4, FALSE) -> 8.92 | D38: =D18 -> ConnorAndyScramble | E38: =IF(VLOOKUP($D38,$A$4:$B$57,2,FALSE)>=E$13,1,0) -> 0 | F38: =IF(VLOOKUP($D38,$A$4:$B$57,2,FALSE)>=F$13,1,0) -> 0 | G38: =IF(VLOOKUP($D38,$A$4:$B$57,2,FALSE)>=G$13,1,0) -> 1 | H38: =IF(VLOOKUP($D38,$A$4:$B$57,2,FALSE)>=H$13,1,0) -> 1 | I38: =IF(VLOOKUP($D38,$A$4:$B$57,2,FALSE)>=I$13,1,0) -> 1 | J38: =IF(VLOOKUP($D38,$A$4:$B$57,2,FALSE)>=J$13,1,0) -> 1 | K38: =IF(VLOOKUP($D38,$A$4:$B$57,2,FALSE)>=K$13,1,0) -> 0 | L38: =IF(VLOOKUP($D38,$A$4:$B$57,2,FALSE)>=L$13,1,0) -> 0 | ... V38: =IF(VLOOKUP($D38,$A$4:$B$57,2,FALSE)>=V$13,1,0) -> 1 | X38: =SUM(E38:M38) -> 5 | Y38: =SUM(N38:V38) -> 5 | Z38: =sum(X38,Y38) -> 10
D39: =D19 -> ConnorAndyAltShot | E39: =IF(VLOOKUP($D39,$A$4:$B$57,2,FALSE)>=E$13,1,0) -> 1 | F39: =IF(VLOOKUP($D39,$A$4:$B$57,2,FALSE)>=F$13,1,0) -> 1 | G39: =IF(VLOOKUP($D39,$A$4:$B$57,2,FALSE)>=G$13,1,0) -> 1 | H39: =IF(VLOOKUP($D39,$A$4:$B$57,2,FALSE)>=H$13,1,0) -> 1 | I39: =IF(VLOOKUP($D39,$A$4:$B$57,2,FALSE)>=I$13,1,0) -> 1 | J39: =IF(VLOOKUP($D39,$A$4:$B$57,2,FALSE)>=J$13,1,0) -> 1 | K39: =IF(VLOOKUP($D39,$A$4:$B$57,2,FALSE)>=K$13,1,0) -> 1 | L39: =IF(VLOOKUP($D39,$A$4:$B$57,2,FALSE)>=L$13,1,0) -> 1 | ... V39: =IF(VLOOKUP($D39,$A$4:$B$57,2,FALSE)>=V$13,1,0) -> 1 | X39: =SUM(E39:M39) -> 9 | Y39: =SUM(N39:V39) -> 9 | Z39: =sum(X39,Y39) -> 18
A40: =$E$3&$E$5&$N$10 -> ColeToveyAltShot | B40: =VLOOKUP($E$3, Information!$B$22:$G$37, 5, FALSE)+VLOOKUP($E$5, Information!$B$22:$G$37, 5, FALSE) -> 18.55 | D40: =D20
C41: Strokes | D41: =D21 -> BrettMattScramble | E41: =IF(VLOOKUP($D41,$A$4:$B$57,2,FALSE)>=E$13,1,0) -> 1 | F41: =IF(VLOOKUP($D41,$A$4:$B$57,2,FALSE)>=F$13,1,0) -> 1 | G41: =IF(VLOOKUP($D41,$A$4:$B$57,2,FALSE)>=G$13,1,0) -> 1 | H41: =IF(VLOOKUP($D41,$A$4:$B$57,2,FALSE)>=H$13,1,0) -> 1 | I41: =IF(VLOOKUP($D41,$A$4:$B$57,2,FALSE)>=I$13,1,0) -> 1 | J41: =IF(VLOOKUP($D41,$A$4:$B$57,2,FALSE)>=J$13,1,0) -> 1 | K41: =IF(VLOOKUP($D41,$A$4:$B$57,2,FALSE)>=K$13,1,0) -> 1 | L41: =IF(VLOOKUP($D41,$A$4:$B$57,2,FALSE)>=L$13,1,0) -> 1 | ... V41: =IF(VLOOKUP($D41,$A$4:$B$57,2,FALSE)>=V$13,1,0) -> 1 | X41: =SUM(E41:M41) -> 9 | Y41: =SUM(N41:V41) -> 8 | Z41: =sum(X41,Y41) -> 17
...
